<?xml version="1.0"?>

<robot xmlns:xacro="http://www.ros.org/wiki/xacro" name="mycar">
        <xacro:property name="footprint_radius" value="0.001" />
        <link name="base_footprint">
            <visual>
                <geometry>
                <sphere radius="${footprint_radius}"/> 
                </geometry>

            </visual>
        </link>
        <!-- xacro封装底盘数据 -->
        <xacro:property name="base_radius" value="0.1" />
        <xacro:property name="base_length" value="0.08" />
        <xacro:property name="lidi" value="0.015" />
        <xacro:property name="base_mass" value="2" />

        <xacro:property name="base_joint_2" value="${base_length / 2 +lidi}" />
        <!-- 底盘 -->
        <link name="base_link">
            <visual>
                <geometry>
                    <!-- yuanzhu -->
                    <cylinder radius="0.1" length="0.08"/>
                    <!-- r=0.1m h=0.08m H=0.015 -->
                </geometry>
                
                <origin xyz="0.0 0.0 0.0" rpy="0.0 0.0 0.0"/>
                
                <material name="color">
                    <color rgba="1 0.5 0.2 0.5" />
                </material>
            </visual>
            <collision>
                <geometry>
                    <!-- yuanzhu -->
                    <cylinder radius="0.1" length="0.08"/>
                    <!-- r=0.1m h=0.08m H=0.015 -->
                </geometry>
                
                <origin xyz="0.0 0.0 0.0" rpy="0.0 0.0 0.0"/>
            </collision>
            <xacro:cylinder_inertial_matrix m="${base_mass}" r="${base_radius}" h="${base_length}" />
        </link>
        <gazebo reference="base_link">
            <material>Gazebo/Yellow</material>
        </gazebo>
        <!-- 底盘关节 -->
        <joint name="link2footprint" type="fixed">
            <parent link="base_footprint"/>
            
            <child link="base_link"/>
            
            <origin xyz="0.0 0.0 0.055" rpy="0.0 0.0 0.0"/>
            
        </joint>
        <!-- 封装轮子数据 -->
        <xacro:property name="wheel_radius" value="0.0325" />
        <xacro:property name="wheel_length" value="0.015" />
        <xacro:property name="wheel_mass" value="0.05" />

        <xacro:property name="PI" value="3.14159" />
        <!-- 计算轮子关节节点 -->
        <xacro:property name="wheel_joint_z" value="${ ( base_length / 2 + lidi -wheel_radius ) * -1 }" />
        
        <!-- 封装左右轮子 -->
        <xacro:macro name="wheel_func" params="wheel_name flag">
            <link name="${wheel_name}_wheel">
                <visual>
                    <geometry>
                        <cylinder radius="0.0325" length="0.015"/>
                    </geometry>
                    <origin xyz="0.0 0.0 0.0" rpy="1.5708 0.0 0.0"/>
                    
                    <material name="wheelscolor">
                        <color rgba="0 0 0 0.3" />
                    </material>
                </visual>
                <collision>
                    <geometry>
                        <cylinder radius="0.0325" length="0.015"/>
                    </geometry>
                    <origin xyz="0.0 0.0 0.0" rpy="1.5708 0.0 0.0"/>
                </collision>
                <xacro:cylinder_inertial_matrix m="${wheel_mass}" r="${wheel_radius}" h="${wheel_length}" />

            </link>

            <gazebo reference="${wheel_name}_wheel">
                <material>Gazebo/Red</material>
            </gazebo>
            <!-- 左右轮子关节 -->
            <joint name="base_${wheel_name}_wheel_joint" type="continuous">
                <parent link="base_link"/>
            
                <child link="${wheel_name}_wheel"/>
                <origin xyz="0.0 ${ 0.1 * flag } ${wheel_joint_z}" rpy="0.0 0.0 0.0"/>
                <axis xyz="0.0 1 0.0"/>
            
            </joint>
            
        </xacro:macro>
        <!-- xacro宏调用左右轮子 -->
        <xacro:wheel_func wheel_name="l" flag="1"/>
        <xacro:wheel_func wheel_name="r" flag="-1"/>
        <!-- 封装万向轮数据 -->
        <xacro:property name="small_wheel_radius" value="0.0075" />
        <xacro:property name="small_wheel_mass" value="0.01" />

        <xacro:property name="small_joint_z" value="${ ( base_length / 2 + lidi - small_wheel_radius ) * -1 }" />
        <!-- 封装万向轮 -->
        <xacro:macro name="small_wheel_func" params="small_wheel_name flag">
                <link name="${small_wheel_name}_wheel">
                    <visual>
                        <geometry>
                            <sphere radius="${small_wheel_radius}"/>
                        </geometry>
                        <origin xyz="0.0 0.0 0.0" rpy="0.0 0.0 0.0"/>
                        <material name="cla">
                            <color rgba="0 0 0 0.3" />
                        </material>

                    </visual>
                    <collision>
                        <geometry>
                            <sphere radius="${small_wheel_radius}"/>
                        </geometry>
                        <origin xyz="0.0 0.0 0.0" rpy="0.0 0.0 0.0"/>
                    </collision>
                    <xacro:sphere_inertial_matrix m="${small_wheel_mass}" r="${small_wheel_radius}"/>
                </link> 
                <gazebo reference="${small_wheel_name}_wheel">
                    <material>Gazebo/Red</material>
                </gazebo>
                
                <!-- 万向轮关节 -->
                <joint name="base1_${small_wheel_name}_wheel_joint" type="continuous">
                    <parent link="base_link"/>
                    
                    <child link="${small_wheel_name}_wheel"/>
                    <origin xyz="${0.08 * flag} 0 ${small_joint_z}" rpy="0.0 0.0 0.0"/>
                    <axis xyz="0.0 1 0.0"/>
                    
                </joint>
                
       
        </xacro:macro>
        <!-- xacro宏调用万向轮 -->
        <xacro:small_wheel_func small_wheel_name="front" flag="1"/>
        <xacro:small_wheel_func small_wheel_name="back" flag="-1"/>

</robot>