<?xml version="1.0"?>

<robot xmlns:xacro="http://www.ros.org/wiki/xacro" name="mycar">
        <xacro:property name="footprint_radius" value="0.001" />
        <link name="base_footprint">
            <visual>
                <geometry>
                <sphere radius="${footprint_radius}"/> 
                </geometry>

            </visual>
        </link>
        
        <xacro:property name="base_radius" value="0.1" />
        <xacro:property name="base_length" value="0.08" />
        <xacro:property name="lidi" value="0.015" />
        <xacro:property name="base_joint_2" value="${base_length / 2 +lidi}" />

        <link name="base_link">
            <visual>
                <geometry>
                    <!-- yuanzhu -->
                    <cylinder radius="0.1" length="0.08"/>
                    <!-- r=0.1m h=0.08m H=0.015 -->
                </geometry>
                
                <origin xyz="0.0 0.0 0.0" rpy="0.0 0.0 0.0"/>
                
                <material name="color">
                    <color rgba="1 0.5 0.2 0.5" />
                </material>
            </visual>
        </link>
        <joint name="link2footprint" type="fixed">
            <parent link="base_footprint"/>
            
            <child link="base_link"/>
            
            <origin xyz="0.0 0.0 0.055" rpy="0.0 0.0 0.0"/>
            
        </joint>
        <xacro:property name="wheel_radius" value="0.0325" />
        <xacro:property name="wheel_length" value="0.015" />
        <xacro:property name="PI" value="3.14159" />
        <xacro:property name="wheel_joint_z" value="${ ( base_length / 2 + lidi -wheel_radius ) * -1 }" />
        
        <xacro:macro name="wheel_func" params="wheel_name flag">
            <link name="${wheel_name}_wheel">
                <visual>
                    <geometry>
                        <cylinder radius="0.0325" length="0.015"/>
                    </geometry>
                    <origin xyz="0.0 0.0 0.0" rpy="1.5708 0.0 0.0"/>
                    
                    <material name="wheelscolor">
                        <color rgba="0 0 0 0.3" />
                    </material>
                </visual>
            </link>
            <joint name="base_${wheel_name}_wheel_joint" type="continuous">
                <parent link="base_link"/>
            
                <child link="${wheel_name}_wheel"/>
                <origin xyz="0.0 ${ 0.1 * flag } ${wheel_joint_z}" rpy="0.0 0.0 0.0"/>
                <axis xyz="0.0 1 0.0"/>
            
            </joint>
            
        </xacro:macro>

        <xacro:wheel_func wheel_name="l" flag="1"/>
        <xacro:wheel_func wheel_name="r" flag="-1"/>

        <xacro:property name="small_wheel_radius" value="0.0075" />
        <xacro:property name="small_joint_z" value="${ ( base_length / 2 + lidi - small_wheel_radius ) * -1 }" />

        <xacro:macro name="small_wheel_func" params="small_wheel_name flag">
                <link name="${small_wheel_name}_wheel">
                    <visual>
                        <geometry>
                            <sphere radius="${small_wheel_radius}"/>
                        </geometry>
                        <origin xyz="0.0 0.0 0.0" rpy="0.0 0.0 0.0"/>
                        <material name="cla">
                            <color rgba="0 0 0 0.3" />
                        </material>

                    </visual>
                </link> 
                
                
                <joint name="base1_${small_wheel_name}_wheel_joint" type="continuous">
                    <parent link="base_link"/>
                    
                    <child link="${small_wheel_name}_wheel"/>
                    <origin xyz="${0.08 * flag} 0 ${small_joint_z}" rpy="0.0 0.0 0.0"/>
                    <axis xyz="0.0 1 0.0"/>
                    
                </joint>
                
       
        </xacro:macro>
        <xacro:small_wheel_func small_wheel_name="front" flag="1"/>
        <xacro:small_wheel_func small_wheel_name="back" flag="-1"/>

</robot>